Workbook

Sheet Дані
C3: Дані для розрахунку
C6: Тип ПВХ-мембрани
B7: 1
C9: Теплоізоляція
B10: 2
C12: Варіант кріплення ПВХ-мембрани до основи
B13: 3
C15: Основа
B16: 4
C18: Товщина теплоізоляції
B19: 5
C21: Розділюючий шар геотекстилю 200 г/м²
B22: 6
C24: Захисний шар геотекстилю 300 г/м²
B25: 7
C27: Виберіть тип пароізоляції
B28: 8
C30: Виберіть тип воронки
B31: 9
C33: Виберіть дренажний геокомпозит
B34: 10
C36: Характеристики покрівлі
B37: 11 | C37: Площа покрівлі | E37: 500 | F37: м²
C38: Периметр покрівлі | E38: 120 | F38: м
C39: Довжина парапету з урахуванням заведення на примикання | E39: 130 | F39: м
E40: 5
E41: 0
E42: 0
E43: 0
C44: Висота заведення на примикання | E44: 0.4 | F44: м
E45: 0.2
E46: 0
E47: 0
E48: 0
C49: Довжина кріплення ПВХ-планки та герметика | E49: 7 | F49: м
C50: Довжина крапельника | E50: 9 | F50: м
C52: *жовті поля для заповнення
D54: Результат!

Sheet Программа
B3: Матеріал | C3: Площа рулона | D3: Корисна площадь при мех. кріплені | E3: Корисна площадь при баластном кріплені | F3: Примикання | G3: Кількість, м.кв
A4: 1 | B4: Покрівельна армована ПВХ-мембрана Soprema Flagon® SR 1,2 мм (2.10х25 м) | C4: =2.1*25 -> 52.5 | D4: =1.98*24.88 -> 49.2624 | E4: =2.02*24.92 -> 50.3384 | F4: Покрівельна неармована ПВХ-мембрана Soprema Flagon® S 1,5 мм (1.05х20 м) | G4: =Дані!$E$37*0.006+$C$35/100*0.6 -> 3.78 | H4: 0
A5: 2 | B5: Покрівельна армована ПВХ-мембрана Soprema Flagon® SR 1,5 мм (2.10х20 м) | C5: =2.1*20 -> 42 | D5: =1.98*19.88 -> 39.3624 | E5: =2.02*19.92 -> 40.2384 | F5: Покрівельна неармована ПВХ-мембрана Soprema Flagon® S 1,5 мм (1.05х20 м) | G5: =Дані!$E$37*0.006+$C$35/100*0.6 -> 3.78 | H5: 0
A6: 3 | B6: Покрівельна армована ПВХ-мембрана Soprema Flagon® SR 1,8 мм (2.10х20 м) | C6: =2.1*20 -> 42 | D6: =D5 -> 39.3624 | E6: =E5 -> 40.2384 | F6: Покрівельна неармована ПВХ-мембрана Soprema Flagon® S 1,5 мм (1.05х20 м) | G6: =Дані!$E$37*0.006+$C$35/100*0.6 -> 3.78 | H6: 0
A7: 4 | B7: Покрівельна армована ПВХ-мембрана Soprema Flagon® SV 1,2 мм (2.10х25 м) | C7: =2.1*25 -> 52.5 | D7: =1.98*24.88 -> 49.2624 | E7: =2.02*24.92 -> 50.3384 | F7: 0 | G7: =Дані!$E$37*0.006+$C$35/100*0.6 -> 3.78 | H7: 0
A8: 5 | B8: Покрівельна армована ПВХ-мембрана Soprema Flagon® SV 1,5 мм (2.10х20 м) | C8: =2.1*20 -> 42 | D8: =D6 -> 39.3624 | E8: =E6 -> 40.2384 | F8: 0 | G8: =Дані!$E$37*0.006+$C$35/100*0.6 -> 3.78 | H8: 0
A9: 6 | B9: Покрівельна армована ПВХ-мембрана Soprema Flagon® SV 1,8 мм (2.10х20 м) | C9: =2.1*20 -> 42 | D9: =D8 -> 39.3624 | E9: 40.24 | F9: 0 | G9: =Дані!$E$37*0.006+$C$35/100*0.6 -> 3.78 | H9: 0
A10: 7 | B10: Покрівельна не армована ПВХ-мембрана Soprema Flagon® BSL 1,2 мм (2.10х25 м) | C10: =2.1*25 -> 52.5 | D10: =1.98*24.88 -> 49.2624 | E10: =2.02*24.92 -> 50.3384 | F10: 0 | G10: 0 | H10: =Дані!$E$37*0.006+$C$35/100*0.6 -> 3.78
A11: 8 | B11: Armourplan SM 1.5 (2,12x20м) | C11: =2.12*20 -> 42.4 | D11: =2*19.88 -> 39.76 | E11: =2.04*19.92 -> 40.6368 | F11: Неармированная ПВХ-мембрана для устройства примыканий Armourplan D 1.5 (1,06x20м) | G11: =Дані!$E$37*0.006+$C$35/100*0.6 -> 3.78 | H11: 0
B12: 1 | C12: =INDEX(C4:C11,$B$12) -> 52.5 | D12: =INDEX(D4:D11,$B$12) -> 49.2624 | E12: =INDEX(E4:E11,$B$12) -> 50.3384 | F12: =INDEX(F4:F11,$B$12) -> Покрівельна неармована ПВХ-мембрана Soprema Flagon® S 1,5 мм (1.05х20 м) | G12: =INDEX(G4:G11,$B$12) -> 3.78 | H12: =INDEX(H4:H11,$B$12) -> 0
B13: =INDEX(B4:B11,$B$12) -> Покрівельна армована ПВХ-мембрана Soprema Flagon® SR 1,2 мм (2.10х25 м)
A15: 2 | B15: Механічний | C15: =D12 -> 49.2624
B16: Баластний | C16: =E12 -> 50.3384
B17: 1 | C17: =INDEX(C15:C16,B17) -> 49.2624
A20: 3 | B20: Розділовий шар
B21: ні | C21: 0
B22: 1 шар | C22: 1
B23: 1 | C23: =INDEX(C21:C22,B23) -> 0
A26: 4 | B26: Захисний шар
B27: ні | C27: 0
B28: 1 шар | C28: 1
B29: 2 шари | C29: 2
B30: 2 | C30: =INDEX(C27:C29,B30) -> 1
A33: 5 | B33: Розрахунок кількості мембрани | C33: Кількість | D33: Одиниці | E33: Всього | F33: Одиниці
B34: Площа покрівлі | C34: =Дані!E37 -> 500 | D34: м.кв. | E34: =C34 -> 500 | F34: м.кв.
B35: Довжина парапету з урахуванням заведення на занітні фонарі | C35: =Дані!E39 -> 130 | D35: м | E35: =C35*C40 -> 67.6 | F35: м.кв.
C36: =Дані!E40 -> 5 | E36: =C36*C41 -> 1.6 | F36: м.кв.
C37: =Дані!E41 -> 0 | E37: =C37*C42 -> 0 | F37: м.кв.
C38: =Дані!E42 -> 0 | E38: =C38*C43 -> 0 | F38: м.кв.
C39: =Дані!E43 -> 0 | E39: =C39*C44 -> 0 | F39: м.кв.
B40: Висота заведення мембрани на парапет | C40: =IF(Дані!E44=0,0,Дані!E44+0.12) -> 0.52 | D40: м | E40: =E35+E36+E37+E38+E39 -> 69.2 | F40: м.кв.
C41: =IF(Дані!E45=0,0,Дані!E45+0.12) -> 0.32
C42: =IF(Дані!E46=0,0,Дані!E46+0.12) -> 0
C43: =IF(Дані!E47=0,0,Дані!E47+0.12) -> 0
C44: =IF(Дані!E48=0,0,Дані!E48+0.12) -> 0
E45: =E34+E40 -> 569.2 | F45: м.кв.
D46: Коефіціент запаса | E46: =Результат!D7/Программа!E45 -> 1.0657215
A49: 6 | B49: Розрахунок планки примикання | C49: Кількість | D49: Ширина планки | E49: Одиниці | F49: Кількість | G49: Одиниці
B50: Довжина примикання (враховується планка примикання) | C50: =Дані!E49 -> 7 | D50: 0.07 | E50: м | F50: =C50*D50 -> 0.49 | G50: м.кв.
B51: Довжина капельника (при зовнішньому водовідведенню) | C51: =Дані!E50 -> 9 | D51: 0.18 | E51: м | F51: =C51*D51 -> 1.62 | G51: м.кв.
...

Sheet Программа2
B3: Материал | C3: Площадь рулона | D3: Полезная площадь при механическом креплении | E3: Полезная площадь при балластном креплении | F3: Примыкания | G3: количество, м.кв
A4: 1 | B4: Vinitex MP 1.2 (2,1x25м) | C4: =2.1*25 -> 52.5 | D4: =1.98*24.88 -> 49.2624 | E4: =2.02*24.92 -> 50.3384 | F4: Неармированная ПВХ-мембрана для устройства примыканий VINITEX SA 1.2 (2,1x20м) | G4: =Дані!$E$37*0.006+$C$32/100*0.6 -> 3.78 | H4: 0
B5: Vinitex MP 1.5 (2,1x20м) | C5: =2.1*20 -> 42 | D5: =1.98*19.88 -> 39.3624 | E5: =2.02*19.92 -> 40.2384 | F5: Неармированная ПВХ-мембрана для устройства примыканий VINITEX SA 1.2 (2,1x20м) | G5: =Дані!$E$37*0.006+$C$32/100*0.6 -> 3.78 | H5: 0
B6: Vinitex SL 1.5 (2,1x25м) | C6: =2.1*25 -> 52.5 | D6: =1.98*24.88 -> 49.2624 | E6: =2.02*24.92 -> 50.3384 | F6: 0 | G6: 0 | H6: =Дані!$E$37*0.006+$C$32/100*0.6 -> 3.78
B7: Ruvimat E12 (2,0x20м) | C7: =2*20 -> 40 | D7: =1.88*19.88 -> 37.3744 | E7: =1.92*19.92 -> 38.2464 | F7: Неармированная ПВХ-мембрана для устройства примыканий VINITEX SA 1.2 (2,1x20м) | G7: =Дані!$E$37*0.006+$C$32/100*0.6 -> 3.78 | H7: 0
B8: Ruvimat E15 (2,0x20м) | C8: =2*20 -> 40 | D8: =1.88*19.88 -> 37.3744 | E8: =1.92*19.92 -> 38.2464 | F8: Неармированная ПВХ-мембрана для устройства примыканий VINITEX SA 1.2 (2,1x20м) | G8: =Дані!$E$37*0.006+$C$32/100*0.6 -> 3.78 | H8: 0
B9: 1 | C9: =INDEX(C4:C8,$B$9) -> 52.5 | D9: =INDEX(D4:D8,$B$9) -> 49.2624 | E9: =INDEX(E4:E8,$B$9) -> 50.3384 | F9: =INDEX(F4:F8,$B$9) -> Неармированная ПВХ-мембрана для устройства примыканий VINITEX SA 1.2 (2,1x20м) | G9: =INDEX(G4:G8,$B$9) -> 3.78 | H9: =INDEX(H4:H8,$B$9) -> 0
B10: =INDEX(B4:B8,$B$9) -> Vinitex MP 1.2 (2,1x25м)
A12: 2 | B12: Механический | C12: =D9 -> 49.2624
B13: Балластный | C13: =E9 -> 50.3384
B14: 1 | C14: =INDEX(C12:C13,B14) -> 49.2624
A17: 3 | B17: Разделительный слой
B18: нет | C18: 0
B19: 1 слой | C19: 1
B20: 1 | C20: =INDEX(C18:C19,B20) -> 0
A23: 4 | B23: Защитный слой
B24: нет | C24: 0
B25: 1 слой | C25: 1
B26: 2 слоя | C26: 2
B27: 2 | C27: =INDEX(C24:C26,B27) -> 1
A30: 5 | B30: Расчет количества мембраны | C30: Количество | D30: Единицы | E30: Всего c запасом | F30: Единицы
B31: Площадь кровли | C31: =Дані!E37 -> 500 | D31: м.кв. | E31: =C31*1.15 -> 575 | F31: м.кв.
B32: Длина парапета с учетом длинны заведения на короба и зенитные фонари | C32: =Дані!E39 -> 130 | D32: м | E32: =C32*(C35+(C33-0.6)*C36) -> 109.135 | F32: м.кв.
B33: Высота заведения мембраны на парапет | C33: =Дані!E44 -> 0.4 | D33: м
E34: =E31+E32 -> 684.135 | F34: м.кв.
B35: Норма ГЭСН для парапета высотой 0,6 м | C35: =86.25/100 -> 0.8625 | D35: Коэффициент запаса | E35: =Результат2!D7/(C31+C32*C33) -> 1.239375
B36: Добавлять или вычитать из нормы при изменеии высоты на 0,1 м | C36: =11.5/100 -> 0.115
A41: 6 | B41: Расчет планки примыкания | C41: Количество | D41: Ширина планки | E41: Единицы | F41: Количество | G41: Единицы
B42: Длина примыканий (учитывается планка примыканий) | C42: =Дані!E49 -> 7 | D42: 0.07 | E42: м | F42: =C42*D42 -> 0.49 | G42: м.кв.
B43: Длина карниза (при наружном водоотводе) | C43: =Дані!E50 -> 9 | D43: 0.18 | E43: м | F43: =C43*D43 -> 1.62 | G43: м.кв.
B44: Общая длина примыканий | C44: =C42+C43 -> 16 | F44: =F42+F43 -> 2.11 | G44: м.кв.
A47: 6 | B47: Расчет пароизоляции | C47: Количество | D47: Единицы | E47: Всего | F47: Единицы
B48: Площадь кровли | C48: =Дані!E37 -> 500 | D48: м.кв. | E48: =C48 -> 500 | F48: м.кв.
B49: Периметр кровли | C49: =Дані!E38 -> 120 | D49: м | E49: =C49*0.25 -> 30 | F49: м.кв.
E50: =E48+E49 -> 530 | F50: м.кв.
D51: Коэффициент запаса | E51: =Результат!D11/Программа2!E50 -> 1.1019778
A54: 7 | B54: Расчет креплений мембраны
B55: Выбор типа основания | C55: Винт | D55: Держатель
B56: Минеральная вата по профлисту | C56: Саморез WB для крепления изоляции к металлу длиной | D56: Телескопический держатель LDK длиной, мм | E56: 1 | F56: 1
B57: Минеральная вата по бетонному основанию | C57: Саморез WB для крепления изоляции к бетону длиной | D57: Телескопический держатель LDK длиной, мм | E57: 2 | F57: 2
...

Sheet Результат
B4: =TODAY() -> 45457
B5: Загальна кількість матеріалів на покрівлю
B6: Назва | D6: Кількість | E6: Одиниці вимірювання
B7: =Программа!B13 -> Покрівельна армована ПВХ-мембрана Soprema Flagon® SR 1,2 мм (2.10х25 м) | D7: =(Программа!E45/Программа!C17*Программа!C12+Программа!H12) -> 606.60869 | E7: м²
B8: =Программа!F12 -> Покрівельна неармована ПВХ-мембрана Soprema Flagon® S 1,5 мм (1.05х20 м) | D8: =Программа!G12 -> 3.78 | E8: м²
B9: Нетканий термічно зміцнений геотекстиль Tipptex® BS 25 (5х100 м) | D9: =Программа!E45/(4.9*99.9)*500*Программа!C30 -> 581.39772 | E9: м²
B10: Нетканий термічно зміцнений геотекстиль Tipptex® BS 16 (5х100 м) | D10: =Программа!E45/(4.9*99.9)*500*Программа!C23 -> 0 | E10: м²
B11: =INDEX(Программа!B126:B128,Программа!B129) -> Пароізоляція: полімер-бітумна мембрана SOPREMA MORTERPLAS SBS FM 3 1м x 13м | D11: =Программа!F129 -> 584.04823 | E11: м²
B12: =Программа!E129 -> Бітумний праймер, кг(л) | D12: =Программа!G129 -> 156.48 | E12: =Программа!H129 -> кг
B13: Ламінований ПВХ-метал товщиною 1,2 мм (1х2 м) | D13: =Программа!F52 -> 2.11 | E13: м²
B14: Морозостійкий УФ-стабілізований герметик Tenalux® 112М (600 мл) | D14: =Дані!E49/100*15 -> 1.05 | E14: кг
B15: =Программа!C112 -> Теплоізоляційна плита TermPIR | D15: =Дані!E37*1.03 -> 515 | E15: м²
B16: =Программа!C70 -> Саморіз для кріплення ізоляції до металу довжиною | C16: =Программа!D104 -> 60 | D16: =IF(B16=0,0,Программа!C75) -> 1750 | E16: шт.
B17: =Программа!D70 -> Телескопічний дюбель LDK довжиною, мм | C17: =Программа!C104 -> 135 | D17: =Программа!C75 -> 1750 | E17: шт.
B18: =Программа!B137 -> Покрівельна воронка утеплена (вертикальна) SitaTrendy DN 100 з ПВХ-фартухом та системою обігріву | D18: =_xlfn.CEILING.MATH(Дані!E37/Программа!C136,1,) -> 2 | E18: шт.
B19: Флюгарка ПВХ Flagon діаметром 75 мм | D19: =Программа!B141 -> 7 | E19: шт.
B20: =Программа!C148 -> - | D20: =Программа!J148 -> 0 | E20: м²
B21: =Программа!I148 -> - | D21: =Программа!H148 -> 0 | E21: м.п.
B22: =Программа!D148 -> - | D22: =Программа!K148 -> 0 | E22: м²
B23: Кріплення для теплоізоляції
B24: =B16 -> Саморіз для кріплення ізоляції до металу довжиною | C24: =C16 -> 60 | D24: =3*Дані!E37 -> 1500 | E24: шт.
B25: =B17 -> Телескопічний дюбель LDK довжиною, мм | C25: =C17 -> 135 | D25: =D24 -> 1500 | E25: шт.
B27: *в розрахунку враховані всі напуски

Sheet Результат2
B4: =TODAY() -> 45457
B5: Общее количество материалов на плоскую кровлю
B6: Наименование | D6: Количество | E6: Единицы измерения
B7: =Программа!B13 -> Покрівельна армована ПВХ-мембрана Soprema Flagon® SR 1,2 мм (2.10х25 м) | D7: =Программа2!E34+Программа2!H9 -> 684.135 | E7: м²
B8: Неармированная ПВХ-мембрана для устройства примыканий Vinitex SA 1.5 (2,1x20м) | D8: =Программа2!G9 -> 3.78 | E8: м²
B9: Нетканый иглопробивной геотекстиль Tipptex BS 25 (5×100м) | D9: =Программа!E45/(4.9*99.9)*500*Программа!C30 -> 581.39772 | E9: м²
B10: Нетканый иглопробивной геотекстиль Tipptex BS 16 (5×100м) | D10: =Программа!E45/(4.9*99.9)*500*Программа!C23 -> 0 | E10: м²
B11: Полиэтиленовая армированная пленка "ПАРОБАРЬЕР" (1.5×50м) | D11: =Программа2!E50/(1.38*49.88)*75 -> 577.47289 | E11: м²
B12: Двусторонняя клеящая лента Lipex (K2) | D12: =D11/75*51.5+Дані!E38/2 -> 456.53139 | E12: м
B13: Лист оцинкованный, ламинированный гомогенной мембраной (1.0×2.0м) | D13: =Программа2!F44 -> 2.11 | E13: м²
B14: Герметик | D14: =Дані!E49/100*10.26 -> 0.7182 | E14: кг
B15: =Программа!C112 -> Теплоізоляційна плита TermPIR | D15: =Дані!E37*1.03 -> 515 | E15: м²
B16: =Программа!C70 -> Саморіз для кріплення ізоляції до металу довжиною | C16: =Программа!D104 -> 60 | D16: =IF(B16=0,0,Программа2!C67) -> 1400 | E16: шт.
B17: =Программа!D70 -> Телескопічний дюбель LDK довжиною, мм | C17: =Программа!C104 -> 135 | D17: =Программа2!C67 -> 1400 | E17: шт.
B18: Воронка внутреннего водоотвода | D18: =CEILING(Дані!E37/700,1) -> 1 | E18: шт.
B19: Дренажная геомембрана Изолит (2х20 м) | D19: =IF(Программа2!$B$106,Программа2!E116,0) -> 0 | E19: м²
B20: Нетканый термически скрепленный геотекстиль TyparSF | D20: =IF(Программа2!$B$106,Программа2!E117,0) -> 0 | E20: м²
B22: *в расчете учтены нахлесты всех материалов
