Workbook
Name OLE_LINK1: Гидроіз!$A$3
Name OLE_LINK1: Зовніш_облиц!$A$3
Name OLE_LINK1: Л_ДБН!$B$3
Name OLE_LINK1: Несуча_покриття!$A$3
Name OLE_LINK1: Облицювання!$A$3
Name OLE_LINK1: Утеплювач!$A$3
Name OLE_LINK1: Ухил!$A$3

Sheet Вихідні дані
A3: Теплотехнічний розрахунок конструкції суміщеного покриття
A5: Вихідні дані
A6: Замовник: | D6: ТОВ«ЕДВАНСІС ГРУП»
A7: Об'єкт: | C7: -
A8: Місце будівництва:
A9: Адреса: | C9: проспект Миру, буд. 99/101 м. Хмельницький
A10: Призначення будинку:
A12: Шари суміщеного покриття:
A13: Внутрішнє облицювання | P13: Товщиною, м
A14: 1. | P14: 0
A15: 2. | P15: 0.02
A17: Несуча конструкція | P17: Товщиною, м
A18: 3. | P18: 0.03
A20: Ухилоутворюючий шар | P20: Товщиною, м
A21: 4. | P21: 0.05
A22: 5. | P22: 0.05
A24: Гідроізоляційний килим/ пароізоляція | P24: Товщиною, м
A25: 6. | P25: 0.00022
A27: Утеплювач
A28: 7.
A29: Додатковий шар теплоізоляції | P29: Товщиною, м
A30: 7.1 | P30: 0.05
A32: Гідроізоляційний килим | P32: Товщиною, м
A33: 8. | P33: 0.0015
A35: Несуча конструкція | P35: Товщиною, м
A36: 9. | P36: 0.02
A38: Зовнішнє покриття та доутеплення | P38: Товщиною, м
A39: 10. | P39: 0.06
A40: 11. | P40: 0.085
D42: - | E42: поля для заповнення
L44: Результат

Sheet Облицювання
B2: Назва матеріалу | C2: Характеристика в сухому стані | F2: Розрахунковий вміст вологи за масою в умовах експлуатації, w, % | H2: Розрахункові характеристики в умовах експлуатації
C3: густина, ρ, кг/м3 | D3: питома теплоємність, с0, кДж/(кг К) | E3: теплопро-відність, λ0, Вт/(м К) | H3: теплопровідність, λр, Вт/(м К) | J3: коефіцієнт теплозасвоєння, s, Вт/(м2К) | L3: коефіцієнт паропроникності, μ, мг/(м год Па)
F4: А | G4: Б | H4: А | I4: Б | J4: А | K4: Б | L4: А,Б
B5: 1 | C5: 2 | D5: 4 | E5: 5 | F5: 6 | G5: 7 | H5: 8 | I5: 9 | J5: 10 | K5: 11 | L5: 12
B6: 1.3. Вироби з природної органічної та неорганічної сировини | H6: 1 | I6: 1
A7: 1 | B7: Плити деревноволокнисті та деревно-стружечні 200 кг/м³ | C7: 200 | D7: 2.3 | E7: 0.06 | F7: 10 | G7: 12 | H7: 0.07 | I7: 0.08 | J7: 1.67 | K7: 1.81 | L7: 0.24
A8: 2 | B8: Плити деревноволокнисті та деревно-стружечні 400 кг/м³ | C8: 400 | D8: 2.3 | E8: 0.08 | F8: 10 | G8: 12 | H8: 0.11 | I8: 0.13 | J8: 2.95 | K8: 3.26 | L8: 0.19
A9: 3 | B9: Плити деревноволокнисті та деревно-стружечні 600 кг/м³ | C9: 600 | D9: 2.3 | E9: 0.11 | F9: 10 | G9: 12 | H9: 0.13 | I9: 0.16 | J9: 3.93 | K9: 4.43 | L9: 0.13
A10: 4 | B10: Плити деревноволокнисті та деревно-стружечні 800 кг/м³ | C10: 800 | D10: 2.3 | E10: 0.13 | F10: 10 | G10: 12 | H10: 0.19 | I10: 0.23 | J10: 5.49 | K10: 6.13 | L10: 0.12
A11: 5 | B11: Плити деревноволокнисті та деревно-стружечні 1000 кг/м³ | C11: 1000 | D11: 2.3 | E11: 0.15 | F11: 10 | G11: 12 | H11: 0.23 | I11: 0.29 | J11: 6.75 | K11: 7.7 | L11: 0.12
B12: 1.6. Розчини теплоізоляційні | H12: 1 | I12: 1
A13: 6 | B13: Розчини цементноперлітові 600 кг/м³ | C13: 600 | D13: 0.84 | E13: 0.14 | F13: 10 | G13: 15 | H13: 0.19 | I13: 0.23 | J13: 3.24 | K13: 3.84 | L13: 0.17
A14: 7 | B14: Розчини цементноперлітові 800 кг/м³ | C14: 800 | D14: 0.84 | E14: 0.16 | F14: 7 | G14: 12 | H14: 0.21 | I14: 0.26 | J14: 3.73 | K14: 4.51 | L14: 0.16
A15: 8 | B15: Розчини цементноперлітові 1000 кг/м³ | C15: 1000 | D15: 0.84 | E15: 0.21 | F15: 7 | G15: 12 | H15: 0.26 | I15: 0.3 | J15: 4.64 | K15: 5.42 | L15: 0.15
A16: 9 | B16: Розчини гіпсоперлітові 400 кг/м³ | C16: 400 | D16: 0.84 | E16: 0.09 | F16: 6 | G16: 10 | H16: 0.13 | I16: 0.15 | J16: 2.03 | K16: 2.35 | L16: 0.53
A17: 10 | B17: Розчини гіпсоперлітові 500 кг/м³ | C17: 500 | D17: 0.84 | E17: 0.12 | F17: 6 | G17: 10 | H17: 0.15 | I17: 0.19 | J17: 2.44 | K17: 2.95 | L17: 0.43
A18: 11 | B18: Розчини цементно-кремнезитові 200 кг/м³ | C18: 200 | D18: 0.84 | E18: 0.063 | F18: 4 | G18: 8 | H18: 0.072 | I18: 0.08 | J18: 1.03 | K18: 1.17 | L18: 0.35
A19: 12 | B19: Розчини цементно-кремнезитові 300 кг/м³ | C19: 300 | D19: 0.84 | E19: 0.073 | F19: 4 | G19: 8 | H19: 0.082 | I19: 0.09 | J19: 1.34 | K19: 1.52 | L19: 0.29
A20: 13 | B20: Розчини цементно-шлакові 1200 кг/м³ | C20: 1200 | D20: 0.84 | E20: 0.35 | F20: 2 | G20: 4 | H20: 0.47 | I20: 0.58 | J20: 6.16 | K20: 7.15 | L20: 0.14
A21: 14 | B21: Розчини цементно-шлакові 1400 кг/м³ | C21: 1400 | D21: 0.84 | E21: 0.41 | F21: 2 | G21: 4 | H21: 0.52 | I21: 0.64 | J21: 7 | K21: 8.11 | L21: 0.11
A22: 15 | B22: Розчини цементнопінополістирольні | C22: 600 | D22: 0.84 | E22: 0.1 | F22: 4 | G22: 10 | H22: 0.12 | I22: 0.17 | J22: 2.33 | K22: 3.06 | L22: 0.07
B23: 2.3. Вироби гіпсові | H23: 1 | I23: 1
A24: 16 | B24: Плити з гіпсу 1000 кг/м³ | C24: 1000 | D24: 0.84 | E24: 0.23 | F24: 4 | G24: 6 | H24: 0.29 | I24: 0.35 | J24: 4.62 | K24: 5.28 | L24: 0.11
A25: 17 | B25: Плити з гіпсу 1200 кг/м³ | C25: 1200 | D25: 0.84 | E25: 0.35 | F25: 4 | G25: 6 | H25: 0.41 | I25: 0.47 | J25: 6.01 | K25: 6.7 | L25: 0.1
A26: 18 | B26: Листи гіпсокартонні 800 кг/м³ | C26: 800 | D26: 0.84 | E26: 0.15 | F26: 4 | G26: 6 | H26: 0.19 | I26: 0.21 | J26: 3.34 | K26: 3.66 | L26: 0.075
B27: 2.5. Деревина та вироби з неї | H27: 1 | I27: 1
A28: 19 | B28: Сосна та ялина поперек волокон | C28: 500 | D28: 2.3 | E28: 0.09 | F28: 15 | G28: 20 | H28: 0.14 | I28: 0.18 | J28: 3.87 | K28: 4.54 | L28: 0.06
A29: 20 | B29: Сосна та ялина уздовж волокон | C29: 500 | D29: 2.3 | E29: 0.18 | F29: 15 | G29: 20 | H29: 0.29 | I29: 0.35 | J29: 5.56 | K29: 6.33 | L29: 0.32
A30: 21 | B30: Дуб поперек волокон | C30: 700 | D30: 2.3 | E30: 0.1 | F30: 10 | G30: 15 | H30: 0.18 | I30: 0.23 | J30: 5 | K30: 5.86 | L30: 0.05
A31: 22 | B31: Дуб уздовж волокон | C31: 700 | D31: 2.3 | E31: 0.23 | F31: 10 | G31: 15 | H31: 0.35 | I31: 0.41 | J31: 6.9 | K31: 7.83 | L31: 0.3
A32: 23 | B32: Фанера клеєна | C32: 600 | D32: 2.3 | E32: 0.12 | F32: 10 | G32: 13 | H32: 0.15 | I32: 0.18 | J32: 4.22 | K32: 4.73 | L32: 0.02
A33: 24 | B33: Картон облицювальний | C33: 1000 | D33: 2.3 | E33: 0.18 | F33: 5 | G33: 10 | H33: 0.21 | I33: 0.23 | J33: 6.2 | K33: 6.75 | L33: 0.06
A34: 25 | B34: Картон будівельний багатошаровий | C34: 650 | D34: 2.3 | E34: 0.13 | F34: 6 | G34: 12 | H34: 0.15 | I34: 0.18 | J34: 4.26 | K34: 4.89 | L34: 0.083
B35: 3.2. Розчини будівельні | H35: 1 | I35: 1
A36: 26 | B36: Розчин цементно-піщаний | C36: 1600 | D36: 0.84 | E36: 0.47 | F36: 2 | G36: 4 | H36: 0.7 | I36: 0.81 | J36: 8.69 | K36: 9.76 | L36: 0.12
A37: 27 | B37: Розчин складний (пісок, вапно, цемент) | C37: 1700 | D37: 0.84 | E37: 0.52 | F37: 2 | G37: 4 | H37: 0.7 | I37: 0.87 | J37: 8.95 | K37: 10.42 | L37: 0.098
A38: 28 | B38: Розчин вапняно-піщаний | C38: 1800 | D38: 0.84 | E38: 0.58 | F38: 2 | G38: 4 | H38: 0.76 | I38: 0.93 | J38: 9.6 | K38: 11.09 | L38: 0.09
B39: 3.3. Облицювання природним каменем та керамічною плиткою | H39: 1 | I39: 1
A40: 29 | B40: Плити та вироби з природного каменю - граніт, гнейс та базальт | C40: 2800 | D40: 0.88 | E40: 3.49 | F40: 0 | G40: 0 | H40: 3.49 | I40: 3.49 | J40: 25.04 | K40: 25.04 | L40: 0.008
A41: 30 | B41: -мармур | C41: 2800 | D41: 0.88 | E41: 2.91 | F41: 0 | G41: 0 | H41: 2.91 | I41: 2.91 | J41: 22.86 | K41: 22.86 | L41: 0.008
...

Sheet Несуча_покриття
B2: Назва матеріалу | C2: Характеристика в сухому стані | F2: Розрахунковий вміст вологи за масою в умовах експлуатації, w, % | H2: Розрахункові характеристики в умовах експлуатації
C3: густина, ρ, кг/м3 | D3: питома теплоємність, с0, кДж/(кг К) | E3: теплопро-відність, λ0, Вт/(м К) | H3: теплопровідність, λр, Вт/(м К) | J3: коефіцієнт теплозасвоєння, s, Вт/(м2К) | L3: коефіцієнт паропроникності, μ, мг/(м год Па)
F4: А | G4: Б | H4: А | I4: Б | J4: А | K4: Б | L4: А,Б
B5: 1 | C5: 2 | D5: 4 | E5: 5 | F5: 6 | G5: 7 | H5: 8 | I5: 9 | J5: 10 | K5: 11 | L5: 12
B6: 2.5. Деревина та вироби з неї | H6: 1 | I6: 1
A7: 1 | B7: ЦСП | C7: 1300 | D7: 2.3 | E7: 0.09 | F7: 15 | G7: 20 | H7: 0.14 | I7: 0.26 | J7: 3.87 | K7: 4.54 | L7: 0.06
A8: 2 | B8: Сосна та ялина уздовж волокон | C8: 500 | D8: 2.3 | E8: 0.18 | F8: 15 | G8: 20 | H8: 0.29 | I8: 0.35 | J8: 5.56 | K8: 6.33 | L8: 0.32
A9: 3 | B9: Дуб поперек волокон | C9: 700 | D9: 2.3 | E9: 0.1 | F9: 10 | G9: 15 | H9: 0.18 | I9: 0.23 | J9: 5 | K9: 5.86 | L9: 0.05
A10: 4 | B10: Дуб уздовж волокон | C10: 700 | D10: 2.3 | E10: 0.23 | F10: 10 | G10: 15 | H10: 0.35 | I10: 0.41 | J10: 6.9 | K10: 7.83 | L10: 0.3
A11: 5 | B11: Фанера клеєна | C11: 600 | D11: 2.3 | E11: 0.12 | F11: 10 | G11: 13 | H11: 0.15 | I11: 0.18 | J11: 4.22 | K11: 4.73 | L11: 0.02
A12: 6 | B12: Картон облицювальний | C12: 1000 | D12: 2.3 | E12: 0.18 | F12: 5 | G12: 10 | H12: 0.21 | I12: 0.23 | J12: 6.2 | K12: 6.75 | L12: 0.06
A13: 7 | B13: Картон будівельний багатошаровий | C13: 650 | D13: 2.3 | E13: 0.13 | F13: 6 | G13: 12 | H13: 0.15 | I13: 0.18 | J13: 4.26 | K13: 4.89 | L13: 0.083
B14: 3.1. Бетони конструкційні | H14: 1 | I14: 1
A15: 1 | B15: Залізобетон | C15: 2500 | D15: 0.84 | E15: 1.69 | F15: 2 | G15: 3 | H15: 1.92 | I15: 2.04 | J15: 17.98 | K15: 18.95 | L15: 0.03
A16: 2 | B16: Бетон на гравію або щебені з природного каменю | C16: 2400 | D16: 0.84 | E16: 1.51 | F16: 2 | G16: 3 | H16: 1.74 | I16: 1.86 | J16: 16.77 | K16: 17.88 | L16: 0.03
B17: 3.6. Метали | H17: 1 | I17: 1
A18: 1 | B18: Сталь арматурна | C18: 7850 | D18: 0.482 | E18: 58 | F18: 0 | G18: 0 | H18: 58 | I18: 58 | J18: 126.5 | K18: 126.5 | L18: 0
A19: 2 | B19: Чавун | C19: 7200 | D19: 0.482 | E19: 50 | F19: 0 | G19: 0 | H19: 50 | I19: 50 | J19: 112.5 | K19: 112.5 | L19: 0
A20: 3 | B20: Алюміній | C20: 2600 | D20: 0.84 | E20: 221 | F20: 0 | G20: 0 | H20: 221 | I20: 221 | J20: 187.6 | K20: 187.6 | L20: 0
A21: 4 | B21: Латунь, мідь | C21: 8500 | D21: 0.42 | E21: 407 | F21: 0 | G21: 0 | H21: 407 | I21: 407 | J21: 326 | K21: 326 | L21: 0
A22: 5 | B22: Скло віконне | C22: 2500 | D22: 0.84 | E22: 0.76 | F22: 0 | G22: 0 | H22: 0.76 | I22: 0.76 | J22: 10.79 | K22: 10.79 | L22: 0
A23: 6 | B23: Немає | H23: 1 | I23: 1 | L23: 1
B24: 10
B25: 18
B27: =INDEX(B6:B23,$B$24) -> Залізобетон | C27: =INDEX(C6:C23,$B$24) -> 2500 | D27: =INDEX(D6:D23,$B$24) -> 0.84 | E27: =INDEX(E6:E23,$B$24) -> 1.69 | F27: =INDEX(F6:F23,$B$24) -> 2 | G27: =INDEX(G6:G23,$B$24) -> 3 | H27: =INDEX(H6:H23,$B$24) -> 1.92 | I27: =INDEX(I6:I23,$B$24) -> 2.04 | ... L27: =INDEX(L6:L23,$B$24) -> 0.03
B28: =INDEX(B6:B23,$B$25) -> Немає | C28: =INDEX(C6:C23,$B$25) -> 0 | D28: =INDEX(D6:D23,$B$25) -> 0 | E28: =INDEX(E6:E23,$B$25) -> 0 | F28: =INDEX(F6:F23,$B$25) -> 0 | G28: =INDEX(G6:G23,$B$25) -> 0 | H28: =INDEX(H6:H23,$B$25) -> 1 | I28: =INDEX(I6:I23,$B$25) -> 1 | ... L28: =INDEX(L6:L23,$B$25) -> 1

Sheet Ухил
B2: Назва матеріалу | C2: Характеристика в сухому стані | F2: Розрахунковий вміст вологи за масою в умовах експлуатації, w, % | H2: Розрахункові характеристики в умовах експлуатації
C3: густина, ρ, кг/м3 | D3: питома теплоємність, с0, кДж/(кг К) | E3: теплопро-відність, λ0, Вт/(м К) | H3: теплопровідність, λр, Вт/(м К) | J3: коефіцієнт теплозасвоєння, s, Вт/(м2К) | L3: коефіцієнт паропроникності, μ, мг/(м год Па)
F4: А | G4: Б | H4: А | I4: Б | J4: А | K4: Б | L4: А,Б
B5: 1 | C5: 2 | D5: 4 | E5: 5 | F5: 6 | G5: 7 | H5: 8 | I5: 9 | J5: 10 | K5: 11 | L5: 12
B6: 1.3. Вироби з природної органічної та неорганічної сировини | H6: 1 | I6: 1
A7: 31 | B7: Вироби цементополістирольні 300 кг/м³ | C7: 300 | D7: 0.84 | E7: 0.076 | F7: 4 | G7: 8 | H7: 0.1 | I7: 0.11 | J7: 1.53 | K7: 1.74 | L7: 0.095
A8: 32 | B8: Плити деревноволокнисті та деревно-стружечні 400 кг/м³ | C8: 400 | D8: 2.3 | E8: 0.08 | F8: 10 | G8: 12 | H8: 0.11 | I8: 0.13 | J8: 2.95 | K8: 3.26 | L8: 0.19
A9: 33 | B9: Плити деревноволокнисті та деревно-стружечні 600 кг/м³ | C9: 600 | D9: 2.3 | E9: 0.11 | F9: 10 | G9: 12 | H9: 0.13 | I9: 0.16 | J9: 3.93 | K9: 4.43 | L9: 0.13
A10: 34 | B10: Плити деревноволокнисті та деревно-стружечні 800 кг/м³ | C10: 800 | D10: 2.3 | E10: 0.13 | F10: 10 | G10: 12 | H10: 0.19 | I10: 0.23 | J10: 5.49 | K10: 6.13 | L10: 0.12
A11: 35 | B11: Плити деревноволокнисті та деревно-стружечні 1000 кг/м³ | C11: 1000 | D11: 2.3 | E11: 0.15 | F11: 10 | G11: 12 | H11: 0.23 | I11: 0.29 | J11: 6.75 | K11: 7.7 | L11: 0.12
B12: 1.4. Бетони теплоізоляційні | H12: 1 | I12: 1
A13: 1 | B13: Пінополістиролбетон | C13: 500 | D13: 0.84 | E13: 0.065 | F13: 4 | G13: 6 | H13: 0.155 | I13: 0.155 | J13: 1.01 | K13: 1.08 | L13: 0.28
A14: 2 | B14: Бетони ніздрюваті 300 кг/м³ | C14: 300 | D14: 0.84 | E14: 0.08 | F14: 4 | G14: 6 | H14: 0.09 | I14: 0.1 | J14: 1.41 | K14: 1.48 | L14: 0.26
A15: 3 | B15: Бетони ніздрюваті 400 кг/м³ | C15: 400 | D15: 0.84 | E15: 0.1 | F15: 4 | G15: 6 | H15: 0.11 | I15: 0.13 | J15: 1.84 | K15: 2.1 | L15: 0.23
A16: 4 | B16: Бетони ніздрюваті 500 кг/м³ | C16: 500 | D16: 0.84 | E16: 0.12 | F16: 4 | G16: 6 | H16: 0.15 | I16: 0.16 | J16: 2.38 | K16: 2.48 | L16: 0.2
A17: 5 | B17: Вермікулітобетон 400 кг/м³ | C17: 400 | D17: 0.84 | E17: 0.09 | F17: 8 | G17: 13 | H17: 0.11 | I17: 0.13 | J17: 1.94 | K17: 2.29 | L17: 0.19
A18: 6 | B18: Вермікулітобетон 600 кг/м³ | C18: 600 | D18: 0.84 | E18: 0.14 | F18: 8 | G18: 13 | H18: 0.16 | I18: 0.17 | J18: 2.87 | K18: 3.21 | L18: 0.15
A19: 7 | B19: Вермікулітобетон 800 кг/м³ | C19: 800 | D19: 0.84 | E19: 0.21 | F19: 8 | G19: 13 | H19: 0.23 | I19: 0.26 | J19: 3.97 | K19: 4.58 | L19: 0.12
B20: 1.5. Матеріали теплоізоляційні засипні | H20: 1 | I20: 1
A21: 1 | B21: Щебінь перлітовий | C21: 300 | D21: 0.84 | E21: 0.112 | F21: 1 | G21: 2 | H21: 0.115 | I21: 0.12 | J21: 1.42 | K21: 1.51 | L21: 0.26
A22: 2 | B22: Гравій шлаковий | C22: 300 | D22: 0.84 | E22: 0.112 | F22: 1 | G22: 3 | H22: 0.12 | I22: 0.13 | J22: 1.56 | K22: 1.65 | L22: 0.22
A23: 3 | B23: Щебінь шлаковий | C23: 350 | D23: 0.84 | E23: 0.162 | F23: 1 | G23: 3 | H23: 0.17 | I23: 0.19 | J23: 2 | K23: 2.16 | L23: 0.21
A24: 4 | B24: Щебінь вермікулітовий | C24: 250 | D24: 0.84 | E24: 0.112 | F24: 2 | G24: 3 | H24: 0.13 | I24: 0.15 | J24: 1.48 | K24: 1.62 | L24: 0.26
A25: 5 | B25: Гравій керамзитовий 200 кг/м³ | C25: 200 | D25: 0.84 | E25: 0.099 | F25: 2 | G25: 3 | H25: 0.11 | I25: 0.12 | J25: 1.22 | K25: 1.3 | L25: 0.26
A26: 6 | B26: Гравій керамзитовий 300 кг/м³ | C26: 300 | D26: 0.84 | E26: 0.14 | F26: 2 | G26: 3 | H26: 0.12 | I26: 0.13 | J26: 1.56 | K26: 1.66 | L26: 0.25
A27: 7 | B27: Гравій керамзитовий 400 кг/м³ | C27: 400 | D27: 0.84 | E27: 0.12 | F27: 2 | G27: 3 | H27: 0.13 | I27: 0.14 | J27: 1.87 | K27: 1.99 | L27: 0.24
A28: 8 | B28: Гравій керамзитовий 600 кг/м³ | C28: 600 | D28: 0.84 | E28: 0.14 | F28: 2 | G28: 3 | H28: 0.17 | I28: 0.2 | J28: 2.62 | K28: 2.91 | L28: 0.23
A29: 9 | B29: Гравій керамзитовий 800 кг/м³ | C29: 800 | D29: 0.84 | E29: 0.18 | F29: 2 | G29: 3 | H29: 0.21 | I29: 0.23 | J29: 3.36 | K29: 3.6 | L29: 0.21
A30: 10 | B30: Щебінь шлакопемзовий | C30: 400 | D30: 0.84 | E30: 0.17 | F30: 2 | G30: 3 | H30: 0.21 | I30: 0.23 | J30: 2.35 | K30: 2.52 | L30: 0.24
A31: 11 | B31: Пісок вермікулітовий 100 кг/м³ | C31: 100 | D31: 0.84 | E31: 0.064 | F31: 1 | G31: 3 | H31: 0.076 | I31: 0.08 | J31: 0.7 | K31: 0.75 | L31: 0.3
A32: 12 | B32: Пісок вермікулітовий 200 кг/м³ | C32: 200 | D32: 0.84 | E32: 0.076 | F32: 1 | G32: 3 | H32: 0.09 | I32: 0.11 | J32: 1.08 | K32: 1.24 | L32: 0.23
A33: 13 | B33: Пісок для будівельних робіт | C33: 1600 | D33: 0.84 | E33: 0.35 | F33: 1 | G33: 2 | H33: 0.47 | I33: 0.58 | J33: 6.95 | K33: 7.91 | L33: 0.17
B34: 1.6. Розчини теплоізоляційні | H34: 1 | I34: 1
A35: 1 | B35: Розчини цементноперлітові 600 кг/м³ | C35: 600 | D35: 0.84 | E35: 0.14 | F35: 10 | G35: 15 | H35: 0.19 | I35: 0.23 | J35: 3.24 | K35: 3.84 | L35: 0.17
A36: 2 | B36: Розчини цементноперлітові 800 кг/м³ | C36: 800 | D36: 0.84 | E36: 0.16 | F36: 7 | G36: 12 | H36: 0.21 | I36: 0.26 | J36: 3.73 | K36: 4.51 | L36: 0.16
A37: 3 | B37: Розчини цементноперлітові 1000 кг/м³ | C37: 1000 | D37: 0.84 | E37: 0.21 | F37: 7 | G37: 12 | H37: 0.26 | I37: 0.3 | J37: 4.64 | K37: 5.42 | L37: 0.15
A38: 4 | B38: Розчини гіпсоперлітові 400 кг/м³ | C38: 400 | D38: 0.84 | E38: 0.09 | F38: 6 | G38: 10 | H38: 0.13 | I38: 0.15 | J38: 2.03 | K38: 2.35 | L38: 0.53
A39: 5 | B39: Розчини гіпсоперлітові 500 кг/м³ | C39: 500 | D39: 0.84 | E39: 0.12 | F39: 6 | G39: 10 | H39: 0.15 | I39: 0.19 | J39: 2.44 | K39: 2.95 | L39: 0.43
A40: 6 | B40: Розчини цементно-кремнезитові 200 кг/м³ | C40: 200 | D40: 0.84 | E40: 0.063 | F40: 4 | G40: 8 | H40: 0.072 | I40: 0.08 | J40: 1.03 | K40: 1.17 | L40: 0.35
A41: 7 | B41: Розчини цементно-кремнезитові 300 кг/м³ | C41: 300 | D41: 0.84 | E41: 0.073 | F41: 4 | G41: 8 | H41: 0.082 | I41: 0.09 | J41: 1.34 | K41: 1.52 | L41: 0.29
...

Sheet Гидроіз
B2: Назва матеріалу | C2: Характеристика в сухому стані | F2: Розрахунковий вміст вологи за масою в умовах експлуатації, w, % | H2: Розрахункові характеристики в умовах експлуатації
C3: густина, ρ, кг/м3 | D3: питома теплоємність, с0, кДж/(кг К) | E3: теплопро-відність, λ0, Вт/(м К) | H3: теплопровідність, λр, Вт/(м К) | J3: коефіцієнт теплозасвоєння, s, Вт/(м2К) | L3: коефіцієнт паропроникності, μ, мг/(м год Па)
F4: А | G4: Б | H4: А | I4: Б | J4: А | K4: Б | L4: А,Б
B5: 1 | C5: 2 | D5: 4 | E5: 5 | F5: 6 | G5: 7 | H5: 8 | I5: 9 | J5: 10 | K5: 11 | L5: 12
B6: 3.5 Матеріали покрівельні, гідроізоляційні та покриття полімерні для підлог | H6: 1 | I6: 1
A7: 1 | B7: Листи азбестоцементні 1600 кг/м³ | C7: 1600 | D7: 0.84 | E7: 0.23 | F7: 2 | G7: 3 | H7: 0.35 | I7: 0.41 | J7: 6.14 | K7: 6.8 | L7: 0.03
A8: 2 | B8: Листи азбестоцементні 1800 кг/м³ | C8: 1800 | D8: 0.84 | E8: 0.35 | F8: 2 | G8: 3 | H8: 0.47 | I8: 0.52 | J8: 7.55 | K8: 8.12 | L8: 0.03
A9: 3 | B9: Матеріали бітумні, бітумно-полімерні покрівельні та гідроізоляційні 1000 кг/м³ | C9: 1000 | D9: 1.68 | E9: 0.17 | F9: 0 | G9: 0 | H9: 0.17 | I9: 0.17 | J9: 4.56 | K9: 4.56 | L9: 0.008
A10: 4 | B10: Матеріали бітумні, бітумно-полімерні покрівельні та гідроізоляційні 1200 кг/м³ | C10: 1200 | D10: 1.68 | E10: 0.22 | F10: 0 | G10: 0 | H10: 0.22 | I10: 0.22 | J10: 5.69 | K10: 5.69 | L10: 0.008
A11: 5 | B11: Матеріали бітумні, бітумно-полімерні покрівельні та гідроізоляційні 1400 кг/м³ | C11: 1400 | D11: 1.68 | E11: 0.27 | F11: 0 | G11: 0 | H11: 0.27 | I11: 0.27 | J11: 6.8 | K11: 6.8 | L11: 0.008
A12: 6 | B12: Асфальтобетон | C12: 2100 | D12: 1.68 | E12: 1.05 | F12: 0 | G12: 0 | H12: 1.05 | I12: 1.05 | J12: 16.43 | K12: 16.43 | L12: 0.008
A13: 7 | B13: Руберойд, пергамін | C13: 600 | D13: 1.68 | E13: 0.17 | F13: 0 | G13: 0 | H13: 0.17 | I13: 0.17 | J13: 3.53 | K13: 3.53 | L13: -
A14: 8 | B14: Мембрана ПВХ | C14: 1000 | D14: 1.47 | E14: 0.33 | F14: 0 | G14: 0 | H14: 0.23 | I14: 0.23 | J14: 5.87 | K14: 5.87 | L14: 0.00011
A15: 9 | B15: Пароізоляційна плівка | C15: 1600 | D15: 1.47 | E15: 0.3 | F15: 0 | G15: 0 | H15: 0.3 | I15: 0.3 | J15: 8.56 | K15: 8.56 | L15: 0
A16: 10 | B16: Лінолеум полівінілхлоридний на тканинній основі 1400 кг/м³ | C16: 1400 | D16: 1.47 | E16: 0.23 | F16: 0 | G16: 0 | H16: 0.23 | I16: 0.23 | J16: 5.87 | K16: 5.87 | L16: 0.002
A17: 11 | B17: Лінолеум полівінілхлоридний на тканинній основі 1600 кг/м³ | C17: 1600 | D17: 1.47 | E17: 0.29 | F17: 0 | G17: 0 | H17: 0.29 | I17: 0.29 | J17: 7.05 | K17: 7.05 | L17: 0.002
A18: 12 | B18: Лінолеум полівінілхлоридний багатошаровий та одношаровий без підоснови 800 кг/м³ | C18: 800 | D18: 1.47 | E18: 0.17 | F18: 0 | G18: 0 | H18: 0.17 | I18: 0.17 | J18: 3.32 | K18: 3.32 | L18: 0.002
A19: 13 | B19: Лінолеум полівінілхлоридний багатошаровий та одношаровий без підоснови 1200 кг/м³ | C19: 1200 | D19: 1.47 | E19: 0.21 | F19: 0 | G19: 0 | H19: 0.21 | I19: 0.21 | J19: 4.51 | K19: 4.51 | L19: 0.02
A20: 14 | B20: Немає | H20: 1 | I20: 1 | L20: 1
B21: 10
B22: 9
B24: =INDEX(B6:B20,$B$21) -> Пароізоляційна плівка | C24: =INDEX(C6:C20,$B$21) -> 1600 | D24: =INDEX(D6:D20,$B$21) -> 1.47 | E24: =INDEX(E6:E20,$B$21) -> 0.3 | F24: =INDEX(F6:F20,$B$21) -> 0 | G24: =INDEX(G6:G20,$B$21) -> 0 | H24: =INDEX(H6:H20,$B$21) -> 0.3 | I24: =INDEX(I6:I20,$B$21) -> 0.3 | ... L24: =INDEX(L6:L20,$B$21) -> 0
B25: =INDEX(B6:B20,$B$22) -> Мембрана ПВХ | C25: =INDEX(C6:C20,$B$22) -> 1000 | D25: =INDEX(D6:D20,$B$22) -> 1.47 | E25: =INDEX(E6:E20,$B$22) -> 0.33 | F25: =INDEX(F6:F20,$B$22) -> 0 | G25: =INDEX(G6:G20,$B$22) -> 0 | H25: =INDEX(H6:H20,$B$22) -> 0.23 | I25: =INDEX(I6:I20,$B$22) -> 0.23 | ... L25: =INDEX(L6:L20,$B$22) -> 0.00011

Sheet Утеплювач
B2: Назва матеріалу | C2: Характеристика в сухому стані | D2: Розрахункові характеристики в умовах експлуатації
C3: густина, ρ, кг/м3 | D3: теплопровідність, λр, Вт/(м К)
D4: А | E4: Б
B5: 1 | C5: 2 | D5: 8 | E5: 9
A6: 22 | B6: TermPIR, 30 кг/м³ | C6: 30 | D6: 0.023 | E6: 0.023
A7: 23 | B7: Monrock Max E плити з мінеральної вати на синтетичному зв’язуючому, 220/115 кг/м³ | C7: 220/115 | D7: 0.0375 | E7: 0.0377
A8: 24 | B8: Roofrock 80 плити з мінеральної вати на синтетичному зв’язуючому, 175 кг/м³ | C8: 175 | D8: 0.038 | E8: 0.038
A9: 25 | B9: Roofrock 30E плити з мінеральної вати на синтетичному зв’язуючому, 100 кг/м³ | C9: 100 | D9: 0.0363 | E9: 0.0363
A10: 26 | B10: Плити пінополістирольні екструзійні, 35 кг/м³ | C10: 35 | D10: 0.035 | E10: 0.035
B11: 2
B12: =INDEX(B6:B10,$B$11) -> Monrock Max E плити з мінеральної вати на синтетичному зв’язуючому, 220/115 кг/м³ | C12: =INDEX(C6:C10,$B$11) -> 220/115 | D12: =INDEX(D6:D10,$B$11) -> 0.0375 | E12: =INDEX(E6:E10,$B$11) -> 0.0377
B16: Додатковий шар
B17: TermPIR, 30 кг/м³ | C17: 30 | D17: 0.023 | E17: 0.023
B18: Monrock Max E плити з мінеральної вати на синтетичному зв’язуючому, 220/115 кг/м³ | C18: 220/115 | D18: 0.0375 | E18: 0.0377
B19: Roofrock 80 плити з мінеральної вати на синтетичному зв’язуючому, 175 кг/м³ | C19: 175 | D19: 0.038 | E19: 0.038
B20: Roofrock 30E плити з мінеральної вати на синтетичному зв’язуючому, 100 кг/м³ | C20: 100 | D20: 0.0363 | E20: 0.0363
B21: Плити пінополістирольні екструзійні, 35 кг/м³ | C21: 35 | D21: 0.035 | E21: 0.035
B22: Немає | C22: - | D22: 1 | E22: 1
B23: 6
B24: =INDEX(B17:B22,$B$23) -> Немає | C24: =INDEX(C17:C22,$B$23) -> - | D24: =INDEX(D17:D22,$B$23) -> 1 | E24: =INDEX(E17:E22,$B$23) -> 1

Sheet Зовніш_облиц
B2: Назва матеріалу | C2: Характеристика в сухому стані | F2: Розрахунковий вміст вологи за масою в умовах експлуатації, w, % | H2: Розрахункові характеристики в умовах експлуатації
C3: густина, ρ, кг/м3 | D3: питома теплоємність, с0, кДж/(кг К) | E3: теплопро-відність, λ0, Вт/(м К) | H3: теплопровідність, λр, Вт/(м К) | J3: коефіцієнт теплозасвоєння, s, Вт/(м2К) | L3: коефіцієнт паропроникності, μ, мг/(м год Па)
F4: А | G4: Б | H4: А | I4: Б | J4: А | K4: Б | L4: А,Б
B5: 1 | C5: 2 | D5: 4 | E5: 5 | F5: 6 | G5: 7 | H5: 8 | I5: 9 | J5: 10 | K5: 11 | L5: 12
B6: 1.4. Бетони теплоізоляційні | H6: 1 | I6: 1
A7: 1 | B7: Мармурова крихта | C7: 200 | D7: 0.84 | E7: 0.065 | F7: 4 | G7: 6 | H7: 0.069 | I7: 0.4 | J7: 1.01 | K7: 0.4 | L7: 0.28
A8: 2 | B8: Бетони ніздрюваті 300 кг/м³ | C8: 300 | D8: 0.84 | E8: 0.08 | F8: 4 | G8: 6 | H8: 0.09 | I8: 0.1 | J8: 1.41 | K8: 1.48 | L8: 0.26
A9: 3 | B9: Бетони ніздрюваті 400 кг/м³ | C9: 400 | D9: 0.84 | E9: 0.1 | F9: 4 | G9: 6 | H9: 0.11 | I9: 0.13 | J9: 1.84 | K9: 2.1 | L9: 0.23
A10: 4 | B10: Бетони ніздрюваті 500 кг/м³ | C10: 500 | D10: 0.84 | E10: 0.12 | F10: 4 | G10: 6 | H10: 0.15 | I10: 0.16 | J10: 2.38 | K10: 2.48 | L10: 0.2
A11: 5 | B11: Вермікулітобетон 400 кг/м³ | C11: 400 | D11: 0.84 | E11: 0.09 | F11: 8 | G11: 13 | H11: 0.11 | I11: 0.13 | J11: 1.94 | K11: 2.29 | L11: 0.19
A12: 6 | B12: Вермікулітобетон 600 кг/м³ | C12: 600 | D12: 0.84 | E12: 0.14 | F12: 8 | G12: 13 | H12: 0.16 | I12: 0.17 | J12: 2.87 | K12: 3.21 | L12: 0.15
A13: 7 | B13: Вермікулітобетон 800 кг/м³ | C13: 800 | D13: 0.84 | E13: 0.21 | F13: 8 | G13: 13 | H13: 0.23 | I13: 0.26 | J13: 3.97 | K13: 4.58 | L13: 0.12
B14: 1.5. Матеріали теплоізоляційні засипні | H14: 1 | I14: 1
A15: 1 | B15: Щебінь перлітовий | C15: 300 | D15: 0.84 | E15: 0.112 | F15: 1 | G15: 2 | H15: 0.115 | I15: 0.12 | J15: 1.42 | K15: 1.51 | L15: 0.26
A16: 2 | B16: Гравій шлаковий | C16: 300 | D16: 0.84 | E16: 0.112 | F16: 1 | G16: 3 | H16: 0.12 | I16: 0.13 | J16: 1.56 | K16: 1.65 | L16: 0.22
A17: 3 | B17: Щебінь шлаковий | C17: 350 | D17: 0.84 | E17: 0.162 | F17: 1 | G17: 3 | H17: 0.17 | I17: 0.19 | J17: 2 | K17: 2.16 | L17: 0.21
A18: 4 | B18: Щебінь вермікулітовий | C18: 250 | D18: 0.84 | E18: 0.112 | F18: 2 | G18: 3 | H18: 0.13 | I18: 0.15 | J18: 1.48 | K18: 1.62 | L18: 0.26
A19: 5 | B19: Гравій керамзитовий 200 кг/м³ | C19: 200 | D19: 0.84 | E19: 0.099 | F19: 2 | G19: 3 | H19: 0.11 | I19: 0.12 | J19: 1.22 | K19: 1.3 | L19: 0.26
A20: 6 | B20: Гравій керамзитовий 300 кг/м³ | C20: 300 | D20: 0.84 | E20: 0.14 | F20: 2 | G20: 3 | H20: 0.12 | I20: 0.13 | J20: 1.56 | K20: 1.66 | L20: 0.25
A21: 7 | B21: Гравій керамзитовий 400 кг/м³ | C21: 400 | D21: 0.84 | E21: 0.12 | F21: 2 | G21: 3 | H21: 0.13 | I21: 0.14 | J21: 1.87 | K21: 1.99 | L21: 0.24
A22: 8 | B22: Гравій керамзитовий 600 кг/м³ | C22: 600 | D22: 0.84 | E22: 0.14 | F22: 2 | G22: 3 | H22: 0.17 | I22: 0.2 | J22: 2.62 | K22: 2.91 | L22: 0.23
A23: 9 | B23: Гравій керамзитовий 800 кг/м³ | C23: 800 | D23: 0.84 | E23: 0.18 | F23: 2 | G23: 3 | H23: 0.21 | I23: 0.23 | J23: 3.36 | K23: 3.6 | L23: 0.21
A24: 10 | B24: Щебінь шлакопемзовий | C24: 400 | D24: 0.84 | E24: 0.17 | F24: 2 | G24: 3 | H24: 0.21 | I24: 0.23 | J24: 2.35 | K24: 2.52 | L24: 0.24
A25: 11 | B25: Пісок вермікулітовий 100 кг/м³ | C25: 100 | D25: 0.84 | E25: 0.064 | F25: 1 | G25: 3 | H25: 0.076 | I25: 0.08 | J25: 0.7 | K25: 0.75 | L25: 0.3
A26: 12 | B26: Пісок вермікулітовий 200 кг/м³ | C26: 200 | D26: 0.84 | E26: 0.076 | F26: 1 | G26: 3 | H26: 0.09 | I26: 0.11 | J26: 1.08 | K26: 1.24 | L26: 0.23
A27: 13 | B27: Пісок для будівельних робіт | C27: 1600 | D27: 0.84 | E27: 0.35 | F27: 1 | G27: 2 | H27: 0.47 | I27: 0.58 | J27: 6.95 | K27: 7.91 | L27: 0.17
B28: 1.6. Розчини теплоізоляційні | H28: 1 | I28: 1
A29: 1 | B29: Розчини цементноперлітові 600 кг/м³ | C29: 600 | D29: 0.84 | E29: 0.14 | F29: 10 | G29: 15 | H29: 0.19 | I29: 0.23 | J29: 3.24 | K29: 3.84 | L29: 0.17
A30: 2 | B30: Розчини цементноперлітові 800 кг/м³ | C30: 800 | D30: 0.84 | E30: 0.16 | F30: 7 | G30: 12 | H30: 0.21 | I30: 0.26 | J30: 3.73 | K30: 4.51 | L30: 0.16
A31: 3 | B31: Розчини цементноперлітові 1000 кг/м³ | C31: 1000 | D31: 0.84 | E31: 0.21 | F31: 7 | G31: 12 | H31: 0.26 | I31: 0.3 | J31: 4.64 | K31: 5.42 | L31: 0.15
A32: 4 | B32: Розчини гіпсоперлітові 400 кг/м³ | C32: 400 | D32: 0.84 | E32: 0.09 | F32: 6 | G32: 10 | H32: 0.13 | I32: 0.15 | J32: 2.03 | K32: 2.35 | L32: 0.53
A33: 5 | B33: Розчини гіпсоперлітові 500 кг/м³ | C33: 500 | D33: 0.84 | E33: 0.12 | F33: 6 | G33: 10 | H33: 0.15 | I33: 0.19 | J33: 2.44 | K33: 2.95 | L33: 0.43
A34: 6 | B34: Розчини цементно-кремнезитові 200 кг/м³ | C34: 200 | D34: 0.84 | E34: 0.063 | F34: 4 | G34: 8 | H34: 0.072 | I34: 0.08 | J34: 1.03 | K34: 1.17 | L34: 0.35
A35: 7 | B35: Розчини цементно-кремнезитові 300 кг/м³ | C35: 300 | D35: 0.84 | E35: 0.073 | F35: 4 | G35: 8 | H35: 0.082 | I35: 0.09 | J35: 1.34 | K35: 1.52 | L35: 0.29
A36: 8 | B36: Розчини цементно-шлакові 1200 кг/м³ | C36: 1200 | D36: 0.84 | E36: 0.35 | F36: 2 | G36: 4 | H36: 0.47 | I36: 0.58 | J36: 6.16 | K36: 7.15 | L36: 0.14
A37: 9 | B37: Розчини цементно-шлакові 1400 кг/м³ | C37: 1400 | D37: 0.84 | E37: 0.41 | F37: 2 | G37: 4 | H37: 0.52 | I37: 0.64 | J37: 7 | K37: 8.11 | L37: 0.11
A38: 10 | B38: Розчини цементнопінополістирольні | C38: 600 | D38: 0.84 | E38: 0.1 | F38: 4 | G38: 10 | H38: 0.12 | I38: 0.17 | J38: 2.33 | K38: 3.06 | L38: 0.07
B39: 2. Утеплювач | H39: 1 | I39: 1
B40: TermPIR, 30 кг/м³ | C40: 30 | H40: 0.023 | I40: 0.023
B41: Monrock Max E плити з мінеральної вати на синтетичному зв’язуючому, 220/110 кг/м³ | C41: 220/110 | H41: 0.0375 | I41: 0.0377
...

Sheet Л_ДБН
C2: Назва матеріалу | D2: Характеристика в сухому стані | G2: Розрахунковий вміст вологи за масою в умовах експлуатації, w, % | I2: Розрахункові характеристики в умовах експлуатації
D3: густина, ρ, кг/м3 | E3: питома теплоємність, с0, кДж/(кг К) | F3: теплопро-відність, λ0, Вт/(м К) | I3: теплопровідність, λр, Вт/(м К) | K3: коефіцієнт теплозасвоєння, s, Вт/(м2К) | M3: коефіцієнт паропроникності, μ, мг/(м год Па)
G4: А | H4: Б | I4: А | J4: Б | K4: А | L4: Б | M4: А,Б
C5: 1 | D5: 2 | E5: 4 | F5: 5 | G5: 6 | H5: 7 | I5: 8 | J5: 9 | K5: 10 | L5: 11 | M5: 12
C6: 1.1. Волокнисті матеріали
A7: 1 | B7: 1 | C7: 1. Плити з мінеральної вати на синтетичному зв’язуючому негофрованої структури, 75 кг/м³ | D7: 75 | E7: 0.84 | F7: 0.047 | G7: 2 | H7: 5 | I7: 0.055 | J7: 0.062 | K7: 0.55 | L7: 0.61 | M7: 0.55
A8: 2 | B8: 2 | C8: 1. Плити з мінеральної вати на синтетичному зв’язуючому негофрованої структури, 125 кг/м³ | D8: 125 | E8: 0.84 | F8: 0.049 | G8: 2 | H8: 5 | I8: 0.06 | J8: 0.07 | K8: 0.73 | L8: 0.82 | M8: 0.49
A9: 3 | B9: 3 | C9: 1. Плити з мінеральної вати на синтетичному зв’язуючому негофрованої структури, 150 кг/м³ | D9: 150 | E9: 0.84 | F9: 0.044 | G9: 2 | H9: 5 | I9: 0.055 | J9: 0.066 | K9: 0.75 | L9: 0.87 | M9: 0.45
A10: 4 | B10: 4 | C10: 1. Плити з мінеральної вати на синтетичному зв’язуючому негофрованої структури, 175 кг/м³ | D10: 175 | E10: 0.84 | F10: 0.046 | G10: 2 | H10: 5 | I10: 0.058 | J10: 0.072 | K10: 0.83 | L10: 0.98 | M10: 0.41
A11: 5 | B11: 5 | C11: 1. Плити з мінеральної вати на синтетичному зв’язуючому негофрованої структури, 200 кг/м³ | D11: 200 | E11: 0.84 | F11: 0.049 | G11: 2 | H11: 5 | I11: 0.064 | J11: 0.081 | K11: 0.93 | L11: 1.11 | M11: 0.37
A12: 6 | B12: 6 | C12: 2. Плити з мінеральної вати на синтетичному зв’язуючому гофрованої структури, 175 кг/м³ | D12: 175 | E12: 0.84 | F12: 0.051 | G12: 2 | H12: 5 | I12: 0.065 | J12: 0.079 | K12: 0.88 | L12: 1.04 | M12: 0.4
A13: 7 | B13: 7 | C13: 2. Плити з мінеральної вати на синтетичному зв’язуючому гофрованої структури, 200 кг/м³ | D13: 200 | E13: 0.84 | F13: 0.053 | G13: 2 | H13: 5 | I13: 0.071 | J13: 0.087 | K13: 0.98 | L13: 1.16 | M13: 0.36
A14: 8 | B14: 8 | C14: 3. Плити мінераловатні гофрованої структури, 70 кг/м³ | D14: 70 | E14: 0.84 | F14: 0.042 | G14: 2 | H14: 5 | I14: 0.05 | J14: 0.055 | K14: 0.49 | L14: 0.54 | M14: 0.54
A15: 9 | B15: 9 | C15: 3. Плити мінераловатні гофрованої структури, 100 кг/м³ | D15: 100 | E15: 0.84 | F15: 0.043 | G15: 2 | H15: 5 | I15: 0.053 | J15: 0.06 | K15: 0.6 | L15: 0.68 | M15: 0.48
A16: 10 | B16: 10 | C16: 3. Плити мінераловатні гофрованої структури, 170 кг/м³ | D16: 170 | E16: 0.84 | F16: 0.045 | G16: 2 | H16: 5 | I16: 0.059 | J16: 0.07 | K16: 0.82 | L16: 0.97 | M16: 0.41
A17: 11 | B17: 11 | C17: 4. Плити з мінеральної вати на синтетичному зв’язуючому (вміст зв’язуючого за масою від 6,5% до 8,0 %), 150 кг/м³ | D17: 150 | E17: 0.84 | F17: 0.044 | G17: 2 | H17: 5 | I17: 0.054 | J17: 0.064 | K17: 0.76 | L17: 0.88 | M17: 0.45
A18: 12 | B18: 12 | C18: 4. Плити з мінеральної вати на синтетичному зв’язуючому (вміст зв’язуючого за масою від 6,5% до 8,0 %), 170 кг/м³ | D18: 170 | E18: 0.84 | F18: 0.045 | G18: 2 | H18: 5 | I18: 0.055 | J18: 0.065 | K18: 0.82 | L18: 0.97 | M18: 0.42
... A58: 52 | B58: 52 | C58: Нет | D58: 0 | E58: 0 | F58: 0 | G58: 0 | H58: 0 | I58: 1 | J58: 1 | K58: 0 | L58: 0 | M58: 1
A59: 53 | C59: 1.2. Полімерні матеріали
A60: 54 | B60: 1 | C60: 19. Плити пінополістирольні, 15 кг/м³ | D60: 15 | E60: 1.34 | F60: 0.04 | G60: 2 | H60: 10 | I60: 0.045 | J60: 0.055 | K60: 0.28 | L60: 0.33 | M60: 0.05
A61: 55 | B61: 2 | C61: 19. Плити пінополістирольні, 25 кг/м³ | D61: 25 | E61: 1.34 | F61: 0.038 | G61: 2 | H61: 10 | I61: 0.043 | J61: 0.053 | K61: 0.34 | L61: 0.4 | M61: 0.05
A62: 56 | B62: 3 | C62: 19. Плити пінополістирольні, 35 кг/м³ | D62: 35 | E62: 1.34 | F62: 0.037 | G62: 2 | H62: 10 | I62: 0.041 | J62: 0.05 | K62: 0.4 | L62: 0.46 | M62: 0.05
A63: 57 | B63: 4 | C63: 19. Плити пінополістирольні, 50 кг/м³ | D63: 50 | E63: 1.34 | F63: 0.034 | G63: 2 | H63: 10 | I63: 0.04 | J63: 0.045 | K63: 0.46 | L63: 0.53 | M63: 0.05
A64: 58 | B64: 5 | C64: 20. Плити пінополістирольні екструзійні, 50 кг/м³ | D64: 50 | E64: 1.34 | F64: 0.033 | G64: 2 | H64: 10 | I64: 0.038 | J64: 0.043 | K64: 0.47 | L64: 0.54 | M64: 0.02
A65: 59 | B65: 6 | C65: 20. Плити пінополістирольні екструзійні, 80 кг/м³ | D65: 80 | E65: 1.34 | F65: 0.035 | G65: 2 | H65: 10 | I65: 0.041 | J65: 0.049 | K65: 0.59 | L65: 0.73 | M65: 0.02
A66: 60 | B66: 7 | C66: 21. Плити пінополістирольні екструзійні, 20 кг/м³ | D66: 20 | E66: 1.34 | F66: 0.037 | G66: 2 | H66: 10 | I66: 0.039 | J66: 0.041 | K66: 0.29 | L66: 0.32 | M66: 0.02
A67: 61 | B67: 8 | C67: 21. Плити пінополістирольні екструзійні, 25 кг/м³ | D67: 25 | E67: 1.34 | F67: 0.036 | G67: 2 | H67: 10 | I67: 0.038 | J67: 0.04 | K67: 0.32 | L67: 0.36 | M67: 0.02
A68: 62 | B68: 9 | C68: 21. Плити пінополістирольні екструзійні, 30 кг/м³ | D68: 30 | E68: 1.34 | F68: 0.035 | G68: 2 | H68: 10 | I68: 0.037 | J68: 0.039 | K68: 0.34 | L68: 0.39 | M68: 0.02
A69: 63 | B69: 10 | C69: 22. Плити пінополістирольні екструзійні, 39 кг/м³ | D69: 39 | E69: 1.45 | F69: 0.034 | G69: 1 | H69: 2 | I69: 0.037 | J69: 0.037 | K69: 0.4 | L69: 0.4 | M69: 0.025
A70: 64 | B70: 11 | C70: 23. Блоки пінополістирольні, 20 кг/м³ | D70: 20 | E70: 1.45 | F70: 0.038 | G70: 2 | H70: 10 | I70: 0.044 | J70: 0.045 | K70: 0.24 | L70: 0.35 | M70: 0.04
A71: 65 | B71: 12 | C71: 23. Блоки пінополістирольні, 30 кг/м³ | D71: 30 | E71: 1.45 | F71: 0.035 | G71: 2 | H71: 10 | I71: 0.041 | J71: 0.043 | K71: 0.29 | L71: 0.42 | M71: 0.04
... A83: 77 | B83: 24 | C83: 28. Вироби зі спіненого хімічно сшитого пінополіетилену, 30 кг/м³ | D83: 30 | E83: 1.34 | F83: 0.038 | G83: 2 | H83: 5 | I83: 0.042 | J83: 0.043 | K83: 0.38 | L83: 0.4 | M83: 0.02
A84: 78 | B84: 25 | C84: Нет | I84: 1 | J84: 1 | M84: 1
A85: 106 | C85: 1.3. Вироби з природної органічної та неорганічної сировини
A86: 107 | B86: 1 | C86: 29. Вироби перлітофосфогельові, 200 кг/м³ | D86: 200 | E86: 1.05 | F86: 0.064 | G86: 3 | H86: 12 | I86: 0.07 | J86: 0.09 | K86: 1.1 | L86: 1.43 | M86: 0.23
A87: 108 | B87: 2 | C87: 29. Вироби перлітофосфогельові, 300 кг/м³ | D87: 300 | E87: 1.05 | F87: 0.076 | G87: 3 | H87: 12 | I87: 0.08 | J87: 0.12 | K87: 1.43 | L87: 2.02 | M87: 0.2
A88: 109 | B88: 3 | C88: 30. Блоки полістиролбетонні стінові 200 кг/м³ | D88: 200 | E88: 1.06 | F88: 0.065 | G88: 4 | H88: 8 | I88: 0.07 | J88: 0.08 | K88: 1.12 | L88: 1.28 | M88: 0.12
A89: 110 | B89: 4 | C89: 30. Блоки полістиролбетонні стінові 300 кг/м³ | D89: 300 | E89: 1.06 | F89: 0.085 | G89: 4 | H89: 8 | I89: 0.09 | J89: 0.11 | K89: 1.55 | L89: 1.83 | M89: 0.1
A90: 111 | B90: 5 | C90: 30. Блоки полістиролбетонні стінові 600 кг/м³ | D90: 600 | E90: 1.06 | F90: 0.145 | G90: 4 | H90: 8 | I90: 0.175 | J90: 0.2 | K90: 3.07 | L90: 3.49 | M90: 0.068
A91: 112 | B91: 6 | C91: 31. Вироби теплоізоляційні перлітоцементні та перлітогипсові 300 кг/м³ | D91: 300 | E91: 0.84 | F91: 0.075 | G91: 10 | H91: 15 | I91: 0.098 | J91: 0.108 | K91: 0.92 | L91: 1.26 | M91: 0.198
...

Sheet Кліматологія
G2: Таблиця Г.2 – Розрахункові значення температури й вологості повітря приміщень
B3: Місто | C3: Температурна зона | D3: Мінімально допустиме значення опору теплопередачі суьіщених покриттів | G3: Призначення будинку | H3: Розрахункова температура внутрішнього повітря, tв, 0С | I3: Розрахункове значення відносної вологості , φв, % | J3: Вологісний режим
D4: * Для будинків садибного типу і будинків до чотирьох поверхів включно
B5: Сімферополь, Джанкой | C5: ІІ | D5: 6 | E5: =D5 -> 6 | G5: Житлові будинки | H5: 20 | I5: 55 | J5: Нормальний
B6: Ялта, Алушта, Керч | C6: ІІ | D6: 6 | E6: =D6 -> 6 | G6: Громадські і адміністративні будинки | H6: 20 | I6: 50 - 60 | J6: Нормальний
B7: Евпаторія, Феодосія | C7: ІІ | D7: 6 | E7: =D7 -> 6 | G7: Лікувальні й дитячі навчальні установи | H7: 21 | I7: 50 | J7: Нормальний
B8: Вінниця | C8: І | D8: 7 | E8: =D8 -> 7 | G8: Дошкільні установи | H8: 22 | I8: 50 | J8: Нормальний
B9: Луцьк | C9: ІІ | D9: 7 | E9: =D9 -> 7 | J9: 2
B10: Дніпро | C10: ІІ | D10: 7 | E10: =D10 -> 7
B11: Донецьк | C11: І | D11: 7 | E11: =D11 -> 7
B12: Житомир | C12: І | D12: 7 | E12: =D12 -> 7
B13: Ужгород | C13: ІІ | D13: 6 | E13: =D13 -> 6
B14: Запоріжжя | C14: ІІ | D14: 6 | E14: =D14 -> 6
B15: Івано-Франківськ | C15: ІІ | D15: 7 | E15: =D15 -> 7
B16: Кропивницький | C16: І | D16: 7 | E16: =D16 -> 7
B17: Київ | C17: І | D17: 7 | E17: =D17 -> 7
B18: Луганськ | C18: І | D18: 7 | E18: =D18 -> 7
B19: Львів | C19: І | D19: 7 | E19: =D19 -> 7
B20: Миколаїв | C20: ІІ | D20: 6 | E20: =D20 -> 6
B21: Одеса | C21: ІІ | D21: 6 | E21: =D21 -> 6
... B31: Чернігів | C31: І | D31: 7 | E31: =D31 -> 7
D32: 24
C33: TRUE | D33: =INDEX(D5:D31,$D$32) -> 7 | E33: =INDEX(E5:E31,$D$32) -> 7
D34: =IF(C33,D33,E33) -> 7

Sheet Пояснювальна
A3: Теплотехнічний розрахунок конструкції суміщеного покриття
A5: Замовник: | E5: ='Вихідні дані'!D6 -> ТОВ«ЕДВАНСІС ГРУП»
A6: Виконувач: | E6: ТОВ "Мізол"
A7: Дата: | D7: =TODAY() -> 45559
A9: 1. Вихідні дані для розрахунку:
A10: Об'єкт: | D10: ='Вихідні дані'!C7 -> -
A11: Місце будівництва: | H11: =INDEX(Кліматологія!B5:B31,Кліматологія!D32) -> Хмельницький
A12: Адреса: | D12: ='Вихідні дані'!C9 -> проспект Миру, буд. 99/101 м. Хмельницький
A13: Призначення будинку: | I13: =INDEX(Кліматологія!G5:G8,Кліматологія!J9) -> Громадські і адміністративні будинки
A14: Розрахункова внутрішня температура tв = | P14: =INDEX(Кліматологія!H5:H8,Кліматологія!J9) -> 20 | R14: °C
A15: Відносна вологість φв = | J15: =INDEX(Кліматологія!I5:I8,Кліматологія!J9) -> 50 - 60 | M15: %
A16: Вологісний режим приміщення - нормальний за таблицею Б1 [1]. Умови
A17: експлуатації, що встановлюються за Додатком Б[1], призначаються за
A18: літерою "Б". Розрахункові значення теплопровідності шарів суміщеного
A19: покриття (λБ) знайдені за додатком А (таблицею А1 [2] згідно із густиною
A20: матеріалу і наведені в таблиці 1.
A38: мал. 1. Конструктивна схема суміщеного покриття
B40: Таблиця 1 - Розрахункові дані
B41: № шару | D41: Найменування шару | N41: Густина ρ0, кг/м³ | Q41: Товщина δ, м | T41: Теплопровідність λip, Вт/(м×К)
B43: 1 | D43: =Облицювання!B62 -> Немає | N43: =Облицювання!C62 -> 0 | Q43: =IF(N43=0,0,'Вихідні дані'!P14) -> 0 | T43: =Облицювання!I62 -> 1
B46: 2 | D46: =Облицювання!B63 -> Немає | N46: =Облицювання!C63 -> 0 | Q46: =IF(N46=0,0,'Вихідні дані'!P15) -> 0 | T46: =Облицювання!I63 -> 1
B49: 3 | D49: =Несуча_покриття!B27 -> Залізобетон | N49: =Несуча_покриття!C27 -> 2500 | Q49: =IF(N49=0,0,'Вихідні дані'!P18) -> 0.03 | T49: =Несуча_покриття!I27 -> 2.04
B52: 4 | D52: =Ухил!B109 -> Немає | N52: =Ухил!C109 -> 0 | Q52: =IF(N52=0,0,'Вихідні дані'!P21) -> 0 | T52: =Ухил!I109 -> 1
B55: 5 | D55: =Ухил!B110 -> Розчин цементно-піщаний | N55: =Ухил!C110 -> 1600 | Q55: =IF(N55=0,0,'Вихідні дані'!P22) -> 0.05 | T55: =Ухил!I110 -> 0.81
B58: 6 | D58: =Гидроіз!B24 -> Пароізоляційна плівка | N58: =Гидроіз!C24 -> 1600 | Q58: =IF(N58=0,0,'Вихідні дані'!P25) -> 0.00022 | T58: =Гидроіз!I24 -> 0.3
B61: Ут. | D61: =Утеплювач!B12 -> Monrock Max E плити з мінеральної вати на синтетичному зв’язуючому, 220/115 кг/м³ | N61: =Утеплювач!C12 -> 220/115 | Q61: ? | T61: =Утеплювач!E12 -> 0.0377
D64: =Утеплювач!B24 -> Немає | N64: =Утеплювач!C24 -> - | Q64: =IF(N64=" - ", 0,'Вихідні дані'!P30) -> 0 | T64: =Утеплювач!E24 -> 1
B67: 7 | D67: =Гидроіз!B25 -> Мембрана ПВХ | N67: =Гидроіз!C25 -> 1000 | Q67: =IF(N67=0,0,'Вихідні дані'!P33) -> 0.0015 | T67: =Гидроіз!I25 -> 0.23
B70: 8 | D70: =Несуча_покриття!B28 -> Немає | N70: =Несуча_покриття!C28 -> 0 | Q70: =IF(N70=0,0,'Вихідні дані'!P36) -> 0 | T70: =Несуча_покриття!I28 -> 1
B73: 9 | D73: =Зовніш_облиц!B110 -> Немає | N73: =Зовніш_облиц!C110 -> 0 | Q73: =IF(N73=0,0,'Вихідні дані'!P39) -> 0 | T73: =Зовніш_облиц!I110 -> 1
B76: 10 | D76: =Зовніш_облиц!B111 -> Немає | N76: =Зовніш_облиц!C111 -> 0 | Q76: =IF(N76=0,0,'Вихідні дані'!P40) -> 0 | T76: =Зовніш_облиц!I111 -> 1
A79: 2. Розрахунок:
A80: Місто | D80: =INDEX(Кліматологія!B5:B31,Кліматологія!D32) -> Хмельницький | L80: (Додаток А[1]) знаходиться в | V80: =INDEX(Кліматологія!C5:C31,Кліматологія!D32) -> І | X80: - й
A81: температурній зоні України. Мінімально допустиме значення опору
A82: теплопередачі суміщеного покриття (згідно з таблицею 1 [1]) становить:
H84: Rqmin = | K84: =Кліматологія!D34 -> 7 | M84: м²/K×Вт
A86: Записуємо формулу (2 [2]) опору теплопередачі для даної
A87: багатошарової конструкції:
A92: Приймаючи RΣ = Rqmin, знаходимо товщину основного утеплювача:
B96: δут = | D96: ( | E96: =K84 -> 7 | G96: - | H96: 1 | J96: - | K96: =Q43 -> 0 | M96: - | N96: =Q46 -> 0 | P96: - | Q96: =Q49 -> 0.03 | S96: - | T96: =Q52 -> 0 | V96: - | W96: =Q55 -> 0.05
...
